Workbook

Sheet Executive Dashboard
A3: CE-018 PROJECT CONTROLS ASSURANCE SCORECARD — NEC4 DECISION READINESS
A4: Scenario S3 — Conflicting commercial and risk records | Report CE018-S3-DR-REV3.4 Rev 3.4 | ISSUED FOR PROJECT MANAGER REVIEW (IFR) — NOT APPROVED
D5: Fictional Demonstration Data — not a contractual assessment or communication.
A7: PROJECT AND EVENT METADATA
A8: Project | B8: Westbridge Station Access and Enabling Works | E8: Project ID | F8: WSAE
A9: Client | B9: Westbridge Transit Authority | E9: Contractor | F9: Northstar Civil Engineering Ltd
A10: Interface organisation | B10: CityRail Operations | E10: Contract scenario | F10: NEC4 ECC demonstration
A11: Event | B11: CE-018 — Restricted access to the Platform 4 worksite | E11: Related early warning | F11: EW-006 — separate earlier warning concerning the same access issue
A12: Assessment data cut-off | B12: 2026-03-31 | E12: Source Register revision | F12: 3.0
A13: Decision owner | B13: Elena Brooks — NEC4 Project Manager | E13: Control owner | F13: Sofia Khan — Project Controls Lead
A14: Prepared by | B14: CE-018 Project Controls Assurance Assistant (configured AI support) | E14: Classification | F14: Fictional Demonstration Data
A16: FOUR-TEST TILES (scores linked to the Four-Test Scorecard worksheet)
A17: T1 — Evidence and version | C17: T2 — Records agree | E17: T3 — Route and clock | G17: T4 — Human authority
A18: ='Four-Test Scorecard'!C5 -> 1 | C18: ='Four-Test Scorecard'!C6 -> 0 | E18: ='Four-Test Scorecard'!C7 -> 1 | G18: ='Four-Test Scorecard'!C8 -> 2
A19: ='Four-Test Scorecard'!D5 -> BOUNDED LIMITATION | C19: ='Four-Test Scorecard'!D6 -> CRITICAL FAILURE | E19: ='Four-Test Scorecard'!D7 -> BOUNDED LIMITATION | G19: ='Four-Test Scorecard'!D8 -> PASS
A21: CONTROL COUNTERS AND ROUTE (formula-driven)
A22: Total four-test score (max 8) | B22: =SUM('Four-Test Scorecard'!C5:C8) -> 4 | E22: RECOMMENDED DECISION-READINESS ROUTE
A23: Critical TEST failures (tests scoring 0) | B23: =COUNTIF('Four-Test Scorecard'!C5:C8,0) -> 1 | E23: =IF('Four-Test Scorecard'!C8=0,"REFER TO PROJECT MANAGER",IF('Four-Test Scorecard'!C6=0,"STOP / RECONCILE",IF('Four-Test Scorecard'!C5=0,"REWORK EVIDENCE PACK",IF('Four-Test Scorecard'!C7=0,"STOP / ESCALATE",IF(COUNTIF('Four-Test Scorecard'!C5:C8,1)>0,"READY WITH CONDITIONS","READY FOR PROJECT MANAGER REVIEW"))))) -> STOP / RECONCILE
A24: Critical assurance EXCEPTIONS | B24: =COUNTIF('Exceptions and Actions'!B6:B15,"Critical") -> 2
A25: Total assurance exceptions | B25: =COUNTA('Exceptions and Actions'!A6,'Exceptions and Actions'!A7,'Exceptions and Actions'!A8,'Exceptions and Actions'!A9,'Exceptions and Actions'!A10,'Exceptions and Actions'!A13,'Exceptions and Actions'!A14,'Exceptions and Actions'!A15) -> 8
A26: NEC4 controls run | B26: =COUNTA('NEC4 Control Cross-Reference'!A5:A16) -> 12 | E26: Route priority: reserved-authority failure (T4=0) > material record conflict (T2=0) > mandatory evidence missing (T1=0) > critical route/clock failure (T3=0) > any score of 1 > all pass. A score of 0 overrides the total score.
A27: Clause 64.1 trigger checks reported | B27: =COUNTA('Clause 64.1 Triggers'!A5:A8) -> 4
A28: Clause 64.1 trigger indications | B28: =COUNTIF('Clause 64.1 Triggers'!D5:D8,"TRIGGER_INDICATED") -> 0 | E28: =IF(B23>0,"CRITICAL TEST FAILURES PRESENT: "&B23&" | CRITICAL ASSURANCE EXCEPTIONS: "&B24,"NO CRITICAL TEST FAILURE") -> CRITICAL TEST FAILURES PRESENT: 1 | CRITICAL ASSURANCE EXCEPTIONS: 2
A29: Registered evidence records reviewed | B29: =COUNTA('Evidence Register'!C6:C29) -> 23
A31: EVIDENCED POSITIONS, DECISION OWNERSHIP AND NEXT ACTION
A32: Schedule effect — conflicting positions | B32: 8 working days (FCST-P07-X) | 10 working days (QUOT-CE018-REVB, CHG-018, CASE-001, UP13 recorded field) | 12 working days (RISK-044-X; also the UP13 date-derived value)
A33: Commercial exposure — conflicting positions | B33: GBP 150,000 (FCST-P07-X) | GBP 185,000 (QUOT-CE018-REVB, CHG-018, CASE-001) | GBP 210,000 (RISK-044-X)
A34: Conflict range | B34: Cost GBP 60,000 (32.4% of the quoted sum). Time 4 working days. No value averaged, repaired or preferred.
A35: Four-Test Result | B35: CRITICAL FAILURE — T2 = 0
A36: Configured NEC4 Process-Assurance Result | B36: CONFIGURED NEC4 PROCESS CONTROL FAILURE — STOP / RECONCILE
A37: Clause 64.1 Trigger Summary | B37: Trigger 1 NOT_TRIGGERED; Trigger 2 PROJECT MANAGER JUDGEMENT; Trigger 3 PROJECT MANAGER JUDGEMENT; Trigger 4 PROJECT MANAGER JUDGEMENT
A38: Pending decision | B38: Project Manager response to Quotation Rev B under Clause 62.3 / 62.6, and determination of the Clause 64.1 trigger-2 indication.
A39: Decision owner | B39: Elena Brooks — NEC4 Project Manager
A40: Next assurance action | B40: Close E-01, E-02, E-04, E-05, E-06 and E-08 through actions A-01 to A-06 with the named record owners, then rerun T1, T2 and T3.
A41: Next action due | B41: 2026-04-08 — assurance action target, not a contractual deadline
A42: Configured contractual response date | B42: 2026-04-11 — RC-03, Clause 62.3 / 62.6, Elena Brooks. Not overdue at the 2026-03-31 cut-off.
A43: Retained human authority | B43: Elena Brooks, NEC4 Project Manager, retains every contractual decision on CE-018.
A44: Revision note | B44: Rev 3.4 is a controlled cross-output wording correction of Rev 3.3. No assessment was rerun and no evidence was re-examined. Two Excel summary cells retained a stale Rev 3.0 next-action sentence that omitted exception E-08 and actions A-01 to A-06. The next-action wording is now held once and used by Word, Excel and JSON alike. No score, control result, trigger, exception, action, owner, date, route or authority statement was changed. Rev 3.4 supersedes Rev 3.3, which superseded Rev 3.2, Rev 3.1 and Rev 3.0.

Sheet Evidence Register
A1: EVIDENCE REGISTER — REGISTERED RECORDS REVIEWED
A2: Controlled by Source_Register.csv / SRC-001 Rev 3.0. Branding assets are formatting only and are excluded from this register.
A4: Required / status | B4: File name | C4: Record ID | D4: Record type | E4: Revision / version status | F4: Evidence owner | G4: Intended use | H4: Citation locator
A5: PERMANENT PROJECT CONTEXT (11 records)
A6: Yes | B6: Source_Register.csv | C6: SRC-001 | D6: Source register | E6: 3.0 / Current | F6: Project Controls Lead | G6: Controls approved Context and scenario evidence | H6: SRC-001 row; all rows
A7: Yes | B7: CE018_Control_Brief.txt | C7: CTRL-001 | D7: Control brief | E7: 3.0 / Current | F7: Project Controls Lead | G7: Permitted task, method, prohibited actions | H7: Rev 3.0 header; Permitted/Prohibited sections
A8: Yes | B8: Actor_Authority_Matrix.csv | C8: CTRL-002 | D8: Authority matrix | E8: 2.1 / Current | F8: Project Controls Lead | G8: Named actors and retained authority | H8: Rows TG, MR, SK, EB, AM, AI
A9: Yes | B9: Route_Clock_Rules.csv | C9: CTRL-003 | D9: Route and clock rules | E9: 3.0 / Current | F9: NEC4 Project Manager | G9: Configured clause periods and due dates | H9: Rows RC-EW, RC-00, RC-01, RC-02, RC-03
A10: Yes | B10: Four_Test_Checklist.csv | C10: CTRL-005 | D10: Assurance checklist | E10: 3.0 / Current | F10: Project Controls Lead | G10: Four tests, scoring and dependencies | H10: Rows T1-T4
A11: Yes | B11: Expected_Response_Structure.txt | C11: CTRL-006 | D11: Response structure | E11: 3.0 / Current | F11: Project Controls Lead | G11: Required report, scorecard and JSON structure | H11: Rev 3.0 sections 1-11
A12: Yes | B12: NEC4_Decision_Readiness_Control_Matrix.csv | C12: CTRL-007 | D12: NEC4 control matrix | E12: 1.0 / Current | F12: NEC4 Project Manager | G12: Configured procedural controls and Clause 64.1 triggers | H12: Rows NEC-01 to NEC-12
A13: Yes | B13: WBS_Hierarchy.csv | C13: WBS-001 | D13: WBS | E13: 1.0 / Current | F13: Planning Manager | G13: Work-package hierarchy | H13: Rows WSAE, WSAE.10, WSAE.20.10, WSAE.30.10, WSAE.30.20
A14: Yes | B14: CBS_Hierarchy.csv | C14: CBS-001 | D14: CBS | E14: 1.0 / Current | F14: Cost Manager | G14: Cost hierarchy | H14: Rows WSAE-C210, C310, C320, C510, C610
A15: Yes | B15: CE018_WBS_Programme_CBS_Crosswalk.csv | C15: XWALK-001 | D15: Crosswalk | E15: 1.0 / Current | F15: Project Controls Lead | G15: Links CE-018 to WBS, activities and CBS | H15: All 5 rows
A16: Yes | B16: CE018_Event_Record.csv | C16: CASE-001 | D16: Event record | E16: 1.1 / Current | F16: Project Controls Lead | G16: Controlled CE-018 facts and cut-off | H16: Single data row
A17: SCENARIO S3 EVIDENCE (12 records attached)
A18: Yes | B18: Email_01_Access_Risk_2026-02-24.eml | C18: CORR-001 | D18: Email | E18: 1.0 / Current | F18: Theo Grant | G18: Emerging operational access constraint | H18: Date 2026-02-24; Message-ID corr-001
A19: Yes | B19: Email_02_EW006_2026-02-25.eml | C19: EW-006 | D19: Early warning email | E19: 1.0 / Current | F19: Marcus Reed | G19: Separate early-warning record on the same access issue | H19: Date 2026-02-25; Message-ID ew-006
A20: Yes | B20: Email_03_Access_Restriction_2026-03-04.eml | C20: ACC-004 | D20: Access confirmation | E20: 1.0 / Current | F20: Theo Grant | G20: Planned versus actual access | H20: Date 2026-03-04; Message-ID acc-004
A21: Yes | B21: Email_04_CE018_Notification_2026-03-05.eml | C21: CE-018 | D21: CE notification email | E21: 1.0 / Current | F21: Marcus Reed | G21: Contractor notification of restricted access | H21: Date 2026-03-05; Message-ID ce-018
A22: Yes | B22: Email_05_PM_Response_2026-03-12.eml | C22: PMR-018 | D22: Project Manager response | E22: 1.0 / Current | F22: Elena Brooks | G22: PM response and quotation request | H22: Date 2026-03-12; Message-ID pmr-018
A23: Yes | B23: Email_06_Quotation_Submission_2026-03-28.eml | C23: QSUB-018 | D23: Quotation submission email | E23: 1.0 / Current | F23: Marcus Reed | G23: Submission route and accompanying-record references | H23: Date 2026-03-28; Message-ID qsub-018
A24: Yes | B24: P6_Activity_Export_AP12.csv | C24: PROG-AP12 | D24: Accepted Programme export | E24: AP12 / Accepted | F24: Planning Manager | G24: What was planned at the event date | H24: Data date 2026-02-20; rows A1100-M9000
A25: Yes | B25: P6_Activity_Export_UP13.csv | C25: PROG-UP13 | D25: Current programme update | E25: UP13 / Current controlled update | F25: Planning Manager | G25: Actual access and current forecast | H25: Data date 2026-03-20; rows A1100-M9000
A26: Yes | B26: CE018_Quotation_RevB.csv | C26: QUOT-CE018-REVB | D26: Quotation | E26: B / Current | F26: Commercial Manager | G26: Quotation assessment details by WBS, activity and CBS | H26: 5 rows; submitted 2026-03-28
A27: Yes | B27: Cost_Forecast_P07_CONFLICT.csv | C27: FCST-P07-X | D27: Scenario forecast (S3 replacement) | E27: P07-X / Current - demonstration conflict | F27: Project Controls Lead | G27: S3 replacement forecast conflicting with quotation | H27: 5 rows; data date 2026-03-31
A28: Yes | B28: Risk_Register_CONFLICT.csv | C28: RISK-044-X | D28: Scenario risk register (S3 replacement) | E28: 7-X / Current - demonstration conflict | F28: Risk Manager | G28: S3 replacement risk record conflicting with quotation and forecast | H28: Single row RISK-044-X
A29: Yes | B29: Change_Register.csv | C29: CHG-018 | D29: Change register | E29: 5 / Current | F29: Change Manager | G29: Status, owner, next action and expected effect | H29: Single row CHG-018
A30: CORRECTLY EXCLUDED BASE RECORDS (replaced in S3)
A31: Correctly excluded | B31: Cost_Forecast_P07.csv | C31: FCST-P07 | D31: Cost forecast | E31: P07 | F31: Project Controls Lead | G31: Base forecast — registered to S1/S2/S4 only; replaced in S3 by FCST-P07-X | H31: SRC-001 row FCST-P07
A32: Correctly excluded | B32: Risk_Register.csv | C32: RISK-044 | D32: Risk register | E32: 7 | F32: Risk Manager | G32: Base risk record — registered to S1/S2/S4 only; replaced in S3 by RISK-044-X | H32: SRC-001 row RISK-044
A34: Non-evidence formatting assets present in the workspace and deliberately excluded from this register: Westbridge_Transit_Authority.png; CE018_Assurance_Assistant.png; Northstar_Civil_Engineering.png; CityRail_Operations.png; Fictional_Demonstration_Data_Badge.png.

Sheet Cross-Record Reconciliation
A1: CROSS-RECORD RECONCILIATION — AP12, UP13, QUOTATION, FORECAST, RISK AND CHANGE
A2: Every position is shown separately. No value has been averaged, repaired or preferred by the assistant.
A4: A. PROGRAMME — ACCEPTED PROGRAMME AP12 AGAINST CURRENT UPDATE UP13
A5: Activity ID | B5: WBS ID | C5: Activity name | D5: AP12 start / finish | E5: AP12 duration (d) / float (d) | F5: UP13 start / finish | G5: UP13 duration (d) / float (d) | H5: UP13 recorded variance (working days) | I5: UP13 status
A6: WSAE-A1150 | B6: WSAE.20.10 | C6: Confirm Platform 4 access window | D6: 2026-02-27 / 2026-02-27 | E6: 1 / 0 | F6: 2026-02-25 / 2026-02-25 | G6: 1 / 0 | H6: 0 | I6: Complete
A7: WSAE-A1200 | B7: WSAE.20.10 | C7: Establish Platform 4 worksite access | D7: 2026-03-04 / 2026-03-04 | E7: 0 / 0 | F7: 2026-03-18 / 2026-03-18 | G7: 0 / -10 | H7: 10 | I7: Complete
A8: WSAE-A1300 | B8: WSAE.30.10 | C8: Platform 4 enabling works | D8: 2026-03-05 / 2026-03-18 | E8: 10 / 2 | F8: 2026-03-19 / 2026-04-01 | G8: 10 / -10 | H8: 10 | I8: In Progress
A9: WSAE-A1400 | B9: WSAE.30.20 | C9: Install temporary services | D9: 2026-03-19 / 2026-03-27 | E9: 7 / 0 | F9: 2026-04-02 / 2026-04-14 | G9: 9 / -10 | H9: 10 | I9: Not Started
A10: WSAE-M9000 | B10: WSAE.10 | C10: Platform 4 worksite ready | D10: 2026-03-27 / 2026-03-27 | E10: 0 / 0 | F10: 2026-04-14 / 2026-04-14 | G10: 0 / -10 | H10: 10 | I10: Not Started
C11: Assistant note — reported, not resolved | D11: AP12 milestone 2026-03-27 | F11: UP13 milestone 2026-04-14 | H11: Recorded field 10; date-derived 12 on a plain 5-day week (E-05) | I11: Conflict
C12: Assistant note — reported, not resolved | D12: A1400 duration 7 d | F12: A1400 duration 9 d | H12: 2-day increase not explained in the quotation basis (E-06) | I12: Conflict
A14: B. COST BY WBS, ACTIVITY AND CBS — QUOTATION REV B AGAINST FORECAST P07-X
A15: WBS ID | B15: Activity ID | C15: CBS code | D15: Cost element | E15: Quotation Rev B (GBP) | F15: Forecast P07-X (GBP) | G15: Variance (GBP) | H15: Risk RISK-044-X (GBP) | I15: Reconciled?
A16: WSAE.20.10 | B16: WSAE-A1200 | C16: WSAE-C210 | D16: Access / Possession Standby | E16: 25000 | F16: 20000 | G16: =F16-E16 -> -5000 | H16: Not allocated | I16: =IF(G16=0,"Yes","No — conflict") -> No — conflict
A17: WSAE.30.10 | B17: WSAE-A1300 | C17: WSAE-C310 | D17: Direct Labour | E17: 55000 | F17: 45000 | G17: =F17-E17 -> -10000 | H17: Not allocated | I17: =IF(G17=0,"Yes","No — conflict") -> No — conflict
A18: WSAE.30.10 | B18: WSAE-A1300 | C18: WSAE-C320 | D18: Plant and Equipment | E18: 35000 | F18: 30000 | G18: =F18-E18 -> -5000 | H18: Not allocated | I18: =IF(G18=0,"Yes","No — conflict") -> No — conflict
A19: WSAE.30.20 | B19: WSAE-A1400 | C19: WSAE-C510 | D19: Time-Related Overheads | E19: 50000 | F19: 40000 | G19: =F19-E19 -> -10000 | H19: Not allocated | I19: =IF(G19=0,"Yes","No — conflict") -> No — conflict
A20: WSAE.10 | B20: WSAE-M9000 | C20: WSAE-C610 | D20: CE-018 Risk Allowance | E20: 20000 | F20: 15000 | G20: =F20-E20 -> -5000 | H20: Not allocated | I20: =IF(G20=0,"Yes","No — conflict") -> No — conflict
D21: TOTAL | E21: =SUM(E16:E20) -> 185000 | F21: =SUM(F16:F20) -> 150000 | G21: =SUM(G16:G20) -> -35000 | H21: 210000 | I21: =IF(G21=0,"Reconciled","MATERIAL CONFLICT") -> MATERIAL CONFLICT
A22: RISK-044-X carries no CBS code, so its GBP 210,000 position cannot be allocated line by line (exception E-04). It is shown at total level only and has not been apportioned by the assistant.
A24: C. MATERIAL TIME AND COST POSITIONS BY RECORD — SHOWN SEPARATELY
A25: Record ID | B25: Revision | C25: Schedule effect (working days) | D25: Cost (GBP) | E25: Record owner | F25: Basis / status | G25: Citation locator | H25: Agrees with quotation? | I25: Reconciliation action
A26: QUOT-CE018-REVB | B26: B | C26: 10 | D26: 185000 | E26: Commercial Manager (submitted by Marcus Reed / Jade Okafor) | F26: Contractor's submitted quotation position | G26: CE018_Quotation_RevB.csv, 5 rows | H26: Baseline | I26: Supply the calculation build-up behind the five amounts (A-06).
A27: FCST-P07-X | B27: P07-X | C27: 8 | D27: 150000 | E27: Sofia Khan — Project Controls Lead | F27: Registered S3 replacement forecast; below the quotation | G27: Cost_Forecast_P07_CONFLICT.csv, 5 rows | H27: No — conflict | I27: Reconcile to the quotation line by line or record a formal variance rationale (A-01).
A28: RISK-044-X | B28: 7-X | C28: 12 | D28: 210000 | E28: Risk Manager | F28: Registered S3 replacement risk record; above the quotation; no CBS breakdown | G28: Risk_Register_CONFLICT.csv, row RISK-044-X | H28: No — conflict | I28: Reconcile the range and apply CBS coding (A-02, A-03).
A29: CHG-018 | B29: 5 | C29: 10 | D29: 185000 | E29: Change Manager / decision owner Elena Brooks | F29: Change register agrees with the quotation | G29: Change_Register.csv, row CHG-018 | H29: Yes | I29: None — agrees with the quotation.
A30: CASE-001 | B30: 1.1 | C30: 10 | D30: 185000 | E30: Project Controls Lead | F30: Controlled event record agrees with the quotation | G30: CE018_Event_Record.csv, single row | H30: Yes | I30: None — agrees with the quotation.
A31: PROG-UP13 | B31: UP13 | C31: 10 recorded / 12 date-derived | E31: Planning Manager | F31: Programme records a 10-working-day variance field; the recorded dates derive 12 on a plain 5-day week | G31: P6_Activity_Export_UP13.csv, WSAE-M9000 | H31: No — conflict | I31: Register the CAL-5D-10H calendar and confirm whether the variance is 10 or 12 working days (A-04).
A33: Distinct cost positions: GBP 150,000 / GBP 185,000 / GBP 210,000 — range GBP 60,000 (32.4% of the quoted sum). Distinct time positions: 8 / 10 / 12 working days — range 4 working days. Each position is reported with its record owner. The assistant has not averaged, repaired, preferred or selected any value.
A35: D. CONFIGURED ROUTE AND CLOCK POSITION (Route_Clock_Rules.csv / CTRL-003 Rev 3.0)
A36: Rule ID | B36: NEC4 ECC reference | C36: Control | D36: Configured due date | E36: Actual date | F36: Status at 2026-03-31 cut-off | G36: Accountable owner | H36: Date type | I36: Overdue?
A37: RC-EW | B37: 15.1 | C37: Early warning recorded | D37: 2026-02-25 | E37: 2026-02-25 | F37: Met | G37: Marcus Reed / Elena Brooks | H37: Configured contractual date | I37: No
A38: RC-00 | B38: 33.1 / 60.1(2) | C38: Access restriction evidenced | D38: No response period configured | E38: 2026-03-04 | F38: Evidence present — PM determination required | G38: Elena Brooks | H38: Configured contractual date | I38: No
A39: RC-01 | B39: 61.4 | C39: Project Manager response to CE notification | D39: 2026-03-12 | E39: 2026-03-12 | F39: Met on the configured date | G39: Elena Brooks | H39: Configured contractual date | I39: No
A40: RC-02 | B40: 62.2 / 62.3 | C40: Quotation and assessment details submitted | D40: 2026-04-02 | E40: 2026-03-28 | F40: Met — content subject to NEC-05 and NEC-10 | G40: Marcus Reed / Elena Brooks | H40: Configured contractual date | I40: No
A41: RC-03 | B41: 62.3 / 62.6 | C41: Project Manager reply to quotation | D41: 2026-04-11 | E41: Not made at cut-off | F41: Pending — not due at the 2026-03-31 cut-off | G41: Elena Brooks | H41: Configured contractual date | I41: No
A42: CHG-018 | B42: n/a (change control) | C42: Change register next action | D42: 2026-04-02 | E42: Not made at cut-off | F42: Pending — not due at the 2026-03-31 cut-off | G42: Elena Brooks | H42: Configured contractual date | I42: No

Sheet Four-Test Scorecard
A1: FOUR-TEST SCORECARD
A2: Scoring: 2 = pass; 1 = bounded limitation; 0 = critical failure. Any score of 0 determines the route irrespective of the total score.
A4: Test ID | B4: Test purpose — what is tested and why it matters | C4: Score | D4: Status | E4: Critical failure | F4: Finding | G4: Evidence citation | H4: Consequence | I4: Required action
A5: T1 | B5: Prevents decisions being taken on missing, superseded or unapproved records. Confirms every required record is present, approved, current and used for its stated purpose. | C5: 1 | D5: BOUNDED LIMITATION | E5: No | F5: All 11 permanent Context files and all 12 registered S3 evidence files are present at their approved revisions. The registered S3 replacements FCST-P07-X Rev P07-X and RISK-044-X Rev 7-X are in use and the base records FCST-P07 and RISK-044 are correctly excluded. Two bounded administrative limitations remain: RISK-044-X carries no CBS code, so its GBP 210,000 position is not linked to a valid CBS account as the crosswalk control requires (E-04); and the CAL-5D-10H calendar referenced by both programme exports is not a registered record, so working-day counts cannot be independently verified (E-05). Neither prevents human review. | G5: Source_Register.csv / SRC-001 Rev 3.0, all rows; Risk_Register_CONFLICT.csv / RISK-044-X Rev 7-X (no cbs_code field); P6_Activity_Export_AP12.csv and P6_Activity_Export_UP13.csv, calendar_id CAL-5D-10H | H5: Bounded evidence-quality actions carried to E-04 and E-05 with named owners and assurance action targets. Does not itself determine the route. | I5: Risk Manager to CBS-code RISK-044-X. Planning Manager to register the CAL-5D-10H calendar definition.
A6: T2 | B6: Tests whether the programme, quotation, forecast, risk and change records support the same time and cost position. | C6: 0 | D6: CRITICAL FAILURE | E6: Yes | F6: The registered records do not describe the same commercial or time position. Cost: Quotation Rev B GBP 185,000; Forecast P07-X GBP 150,000; Risk RISK-044-X GBP 210,000 — a spread of GBP 60,000, equal to 32 per cent of the quoted sum. Time: 10, 8 and 12 working days respectively. The forecast is below the quotation on every one of the five CBS lines (total variance -GBP 35,000); the risk record is GBP 25,000 above it with no CBS breakdown. Separately, UP13 records a 10-working-day milestone variance while its own recorded dates derive 12 on a plain 5-day week, and activity WSAE-A1400 grows from 7 to 9 days between AP12 and UP13 without explanation in the quotation basis. The conflicts are reported in full; no value has been averaged, repaired or preferred. Whether any position is contractually correct is not decided here. | G6: CE018_Quotation_RevB.csv / QUOT-CE018-REVB Rev B; Cost_Forecast_P07_CONFLICT.csv / FCST-P07-X Rev P07-X; Risk_Register_CONFLICT.csv / RISK-044-X Rev 7-X; Change_Register.csv / CHG-018 Rev 5; P6_Activity_Export_UP13.csv / PROG-UP13, WSAE-A1400 and WSAE-M9000 | H6: Critical failure. A score of 0 determines the route irrespective of the total score. The pack cannot be described as ready for decision while a material conflict is unresolved. | I6: Reconcile or formally explain each conflicting position with its named record owner before the Project Manager's assessment (E-01, E-02, E-05, E-06).
A7: T3 | B7: Tests whether the configured communication, responsible role and response period in Route_Clock_Rules.csv have been followed, and whether any configured Clause 64.1 matter is left unowned or undated. | C7: 1 | D7: BOUNDED LIMITATION | E7: No | F7: Every objective route and clock control in Route_Clock_Rules.csv is satisfied or correctly pending-not-due: RC-EW early warning recorded 2026-02-25 against a configured due date of 2026-02-25; RC-00 access evidence present; RC-01 Project Manager response made on the configured date 2026-03-12; RC-02 quotation submitted 2026-03-28 against a due date of 2026-04-02; RC-03 Project Manager reply due 2026-04-11 and correctly pending-not-due at the 2026-03-31 cut-off. No clock is overdue, no wrong route is evidenced and no time-bar concern arises. Three configured Clause 64.1 matters (NEC-09, NEC-10 and NEC-11) are referred to the Project Manager for judgement rather than determined by the assistant. Each is bounded: it carries a named owner, a stated basis and a recorded due date, and none prevents human review. The assistant asserts no trigger indication, so no unresolved Clause 64.1 trigger arises under the configured T3 scoring rule. | G7: Route_Clock_Rules.csv / CTRL-003 Rev 3.0, rows RC-EW, RC-00, RC-01, RC-02, RC-03; NEC4_Decision_Readiness_Control_Matrix.csv / CTRL-007 Rev 1.0, rows NEC-09, NEC-10, NEC-11; Four_Test_Checklist.csv / CTRL-005 Rev 3.0, row T3 | H7: Bounded limitation. Does not determine the route. The three Clause 64.1 matters must be placed before the Project Manager for determination; the assistant reports evidence findings only and does not determine contractual effect. | I7: Refer the Clause 64.1 matters at NEC-09, NEC-10 and NEC-11 to Elena Brooks for determination (E-03, E-07).
A8: T4 | B8: Prevents the assistant from taking a decision reserved to a named NEC4 role, and confirms that notification, assessment, acceptance, instruction and implementation remain with authorised roles. | C8: 2 | D8: PASS | E8: No | F8: Contractual communications already present in the evidence were issued by their authorised roles: the early warning and CE notification by Marcus Reed for the Contractor (EW-006, CE-018); the access confirmations by Theo Grant (CORR-001, ACC-004); the Project Manager response and quotation request by Elena Brooks (PMR-018). No communication was issued or drafted by the assistant, and none was issued by an unauthorised role. Actions taken by the assistant: extract, link, compare, reconcile, cite, flag, score and prepare this review pack. Actions refused and not performed by the assistant: deciding whether CE-018 is a compensation event; deciding entitlement; deciding which commercial position is correct; assessing, accepting or rejecting Quotation Rev B; determining the contractual effect of the Clause 64.1 trigger indication; notifying, instructing, certifying or implementing CE-018. The retained decision is referred to Elena Brooks. | G8: Actor_Authority_Matrix.csv / CTRL-002 Rev 2.1, rows TG, MR, SK, EB, AI; CE018_Control_Brief.txt / CTRL-001 Rev 3.0, Prohibited Actions and Retained Authority; NEC4_Decision_Readiness_Control_Matrix.csv / CTRL-007 Rev 1.0, row NEC-12 | H8: No authority breach. No reserved-authority failure exists, so the route is governed by the material record conflict rather than by referral for authority reasons. | I8: None. Authority boundary maintained; the contractual decision remains with Elena Brooks.
B9: TOTAL SCORE (max 8) | C9: =SUM(C5:C8) -> 4 | D9: =COUNTIF(C5:C8,0)&" critical test failure(s)" -> 1 critical test failure(s)
A11: Reviewer entry (unlocked): record the reviewer's confirmation of each score below. Formula cells on the Executive Dashboard are driven from column C of this table.
A12: Test ID | B12: Reviewer confirmation | C12: Reviewer score | D12: Reviewer | E12: Date | F12: Comment
A13: T1
A14: T2
A15: T3
A16: T4

Sheet NEC4 Control Cross-Reference
A1: NEC4 DECISION-READINESS CONTROL CROSS-REFERENCE — ALL 12 CONFIGURED CONTROLS
A2: Configured process controls from NEC4_Decision_Readiness_Control_Matrix.csv / CTRL-007 Rev 1.0. These are configured demonstration controls, not a claim of NEC4 or legal compliance.
A4: Control ID | B4: Control group | C4: Four-test link | D4: NEC4 ECC reference | E4: Decision-readiness question | F4: Evidence | G4: Result | H4: Finding | I4: Consequence / boundary | J4: Accountable owner | K4: Criticality
A5: NEC-01 | B5: Early warning | C5: T1/T3 | D5: 15.1 | E5: Is there dated evidence that the access risk was warned when it became apparent? | F5: Email_01_Access_Risk_2026-02-24.eml / CORR-001 Rev 1.0; Email_02_EW006_2026-02-25.eml / EW-006 Rev 1.0; Route_Clock_Rules.csv / CTRL-003 row RC-EW | G5: PASSED | H5: The operational constraint was raised 2026-02-24 and the Contractor's early warning was recorded 2026-02-25, meeting the configured RC-EW due date of 2026-02-25. EW-006 and CE-018 remain separate records; the early warning did not become the compensation event. | I5: Objective dates met. Whether the warning was sufficiently prompt in contractual terms remains a Project Manager judgement. | J5: Marcus Reed / Elena Brooks | K5: Major
A6: NEC-02 | B6: Access and event basis | C6: T1/T3 | D6: 33.1 / 60.1(2) | E6: Do the Accepted Programme and access record evidence the planned access date and the actual restriction? | F6: P6_Activity_Export_AP12.csv / PROG-AP12, WSAE-A1200 (planned 2026-03-04); Email_03_Access_Restriction_2026-03-04.eml / ACC-004 Rev 1.0; Email_04_CE018_Notification_2026-03-05.eml / CE-018 Rev 1.0 | G6: EVIDENCED_PM_DETERMINATION | H6: AP12 evidences the planned access date of 2026-03-04. ACC-004 evidences that the planned 8-hour window was not available and that a 2-hour escorted window was provided instead. The candidate event basis is evidenced and referred to the Project Manager. | I6: The assistant evidences the candidate basis only. It has not decided and must not decide that a compensation event exists or that entitlement follows. | J6: Elena Brooks | K6: Critical evidence and authority
A7: NEC-03 | B7: Contractor notification | C7: T1/T3 | D7: 61.3 | E7: Was the Contractor notification separately recorded, correctly routed and within the configured time-bar control? | F7: Email_04_CE018_Notification_2026-03-05.eml / CE-018 Rev 1.0; Email_02_EW006_2026-02-25.eml / EW-006 Rev 1.0; Source_Register.csv / SRC-001 Rev 3.0 | G7: PASSED | H7: The notification was issued by Marcus Reed to Elena Brooks on 2026-03-05, one working day after the 2026-03-04 restriction, and is recorded separately from EW-006 under its own record ID and Message-ID. Routing matches the Authority Matrix. No separate Clause 61.3 period is configured in Route_Clock_Rules.csv, so only the objective elapsed time is reported. | I7: No time-bar concern arises on the objective dates. Whether any contractual exception applies is not decided by the assistant. | J7: Marcus Reed | K7: Critical
A8: NEC-04 | B8: PM notification response | C8: T3 | D8: 61.4 | E8: Did the Project Manager respond within the configured one-week period? | F8: Email_05_PM_Response_2026-03-12.eml / PMR-018 Rev 1.0; Route_Clock_Rules.csv / CTRL-003 row RC-01 | G8: PASSED | H8: RC-01 sets a trigger date of 2026-03-05 with a configured one-week period and a due date of 2026-03-12. The Project Manager response is dated 2026-03-12, on the configured date. | I8: Configured clock met. No escalation required. | J8: Elena Brooks | K8: Critical clock
A9: NEC-05 | B9: Quotation content | C9: T1/T2/T3 | D9: 62.2 | E9: Does the quotation pack contain assessment details and, where remaining work is altered, the required alterations to the Accepted Programme? | F9: CE018_Quotation_RevB.csv / QUOT-CE018-REVB Rev B, 5 rows; Email_06_Quotation_Submission_2026-03-28.eml / QSUB-018 Rev 1.0; P6_Activity_Export_AP12.csv / PROG-AP12; P6_Activity_Export_UP13.csv / PROG-UP13 | G9: CONDITIONAL | H9: Assessment details are present and structured: each of the five quotation lines carries WBS, activity, CBS code, cost element, amount, schedule effect and a narrative basis, and QSUB-018 expressly links AP12, UP13 and the affected activities and CBS accounts. Two conditions remain. First, no calculation build-up (rates, quantities or durations) supports the narrative basis. Second, the supporting records the Contractor cites do not agree with the quoted position, and UP13 is a current update rather than an accepted programme. | I9: Content presence is evidenced; contractual sufficiency is not. The Clause 62.2 assessment-detail check has been explicitly performed and is reported as conditional, not satisfied. | J9: Marcus Reed / Elena Brooks | K9: Critical content
A10: NEC-06 | B10: Quotation submission clock | C10: T3 | D10: 62.3 | E10: Was the quotation and assessment detail submitted within the configured three-week period? | F10: Email_06_Quotation_Submission_2026-03-28.eml / QSUB-018 Rev 1.0; CE018_Quotation_RevB.csv / QUOT-CE018-REVB Rev B; Route_Clock_Rules.csv / CTRL-003 row RC-02 | G10: PASSED | H10: RC-02 sets a trigger date of 2026-03-12, a configured three-week period and a due date of 2026-04-02. The quotation was submitted 2026-03-28, five calendar days inside the configured period. | I10: Configured clock met. Content adequacy is assessed separately under NEC-05 and NEC-10. | J10: Marcus Reed | K10: Critical clock
A11: NEC-07 | B11: PM quotation response | C11: T3/T4 | D11: 62.3 / 62.6 | E11: Is the Project Manager response recorded, or correctly classified as pending-not-due at the cut-off? | F11: Route_Clock_Rules.csv / CTRL-003 row RC-03; Change_Register.csv / CHG-018 Rev 5; CE018_Event_Record.csv / CASE-001 Rev 1.1 | G11: PENDING_NOT_DUE | H11: RC-03 sets a trigger date of 2026-03-28, a configured two-week period and a due date of 2026-04-11. At the 2026-03-31 evidence cut-off the response is not yet due and no decision record exists. CHG-018 records decision status 'Not yet decided' with a next action due 2026-04-02. | I11: Not overdue and does not prevent review. The assistant has not inferred, drafted or issued the Project Manager's response. | J11: Elena Brooks | K11: Critical clock and authority
A12: NEC-08 | B12: Clause 64.1 trigger 1 | C12: T2/T3 | D12: 64.1 — late/missing quotation | E12: Has the Contractor failed to submit the quotation and assessment details within the permitted time? | F12: Email_05_PM_Response_2026-03-12.eml / PMR-018 Rev 1.0; Email_06_Quotation_Submission_2026-03-28.eml / QSUB-018 Rev 1.0; CE018_Quotation_RevB.csv / QUOT-CE018-REVB Rev B; Route_Clock_Rules.csv / CTRL-003 row RC-02 | G12: NOT_TRIGGERED | H12: A quotation with assessment details was submitted on 2026-03-28, inside the configured period ending 2026-04-02. Neither the quotation nor the assessment details are absent or late. | I12: No trigger on this limb. Content quality is reported under NEC-05, not here. | J12: Elena Brooks | K12: Critical
A13: NEC-09 | B13: Clause 64.1 trigger 2 | C13: T2/T3 | D13: 64.1 — incorrect assessment | E13: Is there a material inconsistency or unsupported basis that may indicate the Contractor's assessment is not correct? | F13: CE018_Quotation_RevB.csv / QUOT-CE018-REVB Rev B; Cost_Forecast_P07_CONFLICT.csv / FCST-P07-X Rev P07-X; Risk_Register_CONFLICT.csv / RISK-044-X Rev 7-X; P6_Activity_Export_UP13.csv / PROG-UP13 | G13: PM_JUDGEMENT | H13: MATERIAL CONFLICT IDENTIFIED — PROJECT MANAGER DETERMINATION REQUIRED. Three registered records state three different time and cost positions for the same event: GBP 185,000 / 10 days, GBP 150,000 / 8 days and GBP 210,000 / 12 days. No calculation build-up supports the quoted figures, and UP13 carries an internal inconsistency between its recorded 10-day variance field and the 12 working days derived from its own dates. The registered records therefore provide objective evidence of conflicting cost and time positions. | I13: The assistant must not decide that the Contractor assessed the compensation event incorrectly. Objective conflict is evidenced; whether that conflict means the assessment is incorrect for Clause 64.1 purposes is a determination reserved to Elena Brooks, NEC4 Project Manager. | J13: Elena Brooks | K13: Critical judgement
A14: NEC-10 | B14: Clause 64.1 trigger 3 | C14: T1/T2/T3 | D14: 62.2 / 64.1 — programme alteration missing | E14: Where the event alters remaining work, was the required programme or alteration submitted with the quotation pack? | F14: Email_06_Quotation_Submission_2026-03-28.eml / QSUB-018 Rev 1.0; P6_Activity_Export_UP13.csv / PROG-UP13; P6_Activity_Export_AP12.csv / PROG-AP12; CE018_Quotation_RevB.csv / QUOT-CE018-REVB Rev B | G14: PM_JUDGEMENT | H14: UP13 is a periodic current programme update linked to the quotation. It evidences changed activities for WSAE-A1300, WSAE-A1400 and WSAE-M9000, and QSUB-018 expressly references AP12, UP13 and those activities. It does not conclusively establish that the specific alterations to the Accepted Programme required by Clause 62.2 were submitted as part of the quotation assessment. | I14: The assistant must not determine contractual sufficiency. Presence and linkage of a current programme update are evidenced; whether that update constitutes the required Clause 62.2 alterations is reserved to Elena Brooks. This treatment is consistent with the approved S1 treatment of the same programme evidence. | J14: Marcus Reed / Elena Brooks | K14: Critical
A15: NEC-11 | B15: Clause 64.1 trigger 4 | C15: T1/T3 | D15: 31.1 / 31.3 / 32.2 / 64.1 — latest programme not accepted | E15: Is an Accepted Programme available and is any relevant non-acceptance status identified? | F15: P6_Activity_Export_AP12.csv / PROG-AP12 Rev AP12 (programme_status 'Accepted Programme'); P6_Activity_Export_UP13.csv / PROG-UP13 Rev UP13 (programme_status 'Current Update'); Source_Register.csv / SRC-001 Rev 3.0 | G15: PM_JUDGEMENT | H15: An Accepted Programme is available: AP12 is registered and carries accepted status, and it has not been substituted by UP13 anywhere in this assessment. However, no Project Manager acceptance or non-acceptance record exists for UP13 in the registered evidence, so its status can be neither confirmed nor excluded without inference. | I15: Referred to the Project Manager. The assistant distinguishes AP12 from UP13 and does not treat an update as accepted without evidence. | J15: Elena Brooks | K15: Critical
A16: NEC-12 | B16: Retained human authority | C16: T4 | D16: Clauses 61-64 and Authority Matrix | E16: Are the remaining notification, assessment, acceptance, instruction and implementation actions reserved to the named NEC4 role? | F16: Actor_Authority_Matrix.csv / CTRL-002 Rev 2.1, rows EB, MR, SK, AI; CE018_Control_Brief.txt / CTRL-001 Rev 3.0, Prohibited Actions and Retained Authority | G16: PASSED | H16: All remaining contractual actions — the Clause 62.3/62.6 response, any Clause 64.1 determination, acceptance or rejection of the quotation, and implementation — are reserved to Elena Brooks and are recorded as reserved in this pack. The assistant prepared cited review material only and took no reserved action. | I16: No authority breach. The route is not driven by an authority failure. | J16: Elena Brooks | K16: Critical authority
A18: ="Controls run: "&COUNTA(A5:A16)&" | PASSED: "&COUNTIF(G5:G16,"PASSED")&" | CONDITIONAL: "&COUNTIF(G5:G16,"CONDITIONAL")&" | PENDING_NOT_DUE: "&COUNTIF(G5:G16,"PENDING_NOT_DUE")&" | TRIGGER_INDICATED: "&COUNTIF(G5:G16,"TRIGGER_INDICATED")&" | PM_JUDGEMENT: "&COUNTIF(G5:G16,"PM_JUDGEMENT") -> Controls run: 12 | PASSED: 5 | CONDITIONAL: 1 | PENDING_NOT_DUE: 1 | TRIGGER_INDICATED: 0 | PM_JUDGEMENT: 3
A19: Clause 62.2 check (NEC-05): explicitly performed. Result CONDITIONAL — assessment details are present by WBS, activity and CBS and are linked to AP12 and UP13 through QSUB-018, but no calculation build-up supports the amounts and the Contractor's own supporting records conflict. Configured NEC4 Process-Assurance Result: CONFIGURED NEC4 PROCESS CONTROL FAILURE — STOP / RECONCILE

Sheet Clause 64.1 Triggers
A1: CLAUSE 64.1 INTERVENTION TRIGGERS — ALL FOUR CHECKS REPORTED SEPARATELY
A2: Evidence Finding | Contractual Status | Basis. The assistant reports evidence only. Contractual effect is determined by Elena Brooks, NEC4 Project Manager.
A4: Trigger | B4: Control ID | C4: Evidence finding | D4: Contractual status | E4: Basis / citation
A5: Trigger 1 — Clause 64.1, late or missing quotation | B5: NEC-08 | C5: Quotation Rev B and its assessment details were submitted on 2026-03-28, within the configured period ending 2026-04-02 (RC-02). Nothing required is absent or late. | D5: NOT_TRIGGERED | E5: Route_Clock_Rules.csv / CTRL-003 Rev 3.0 row RC-02; Email_06_Quotation_Submission_2026-03-28.eml / QSUB-018 Rev 1.0; CE018_Quotation_RevB.csv / QUOT-CE018-REVB Rev B
A6: Trigger 2 — Clause 64.1, assessment may not be correct | B6: NEC-09 | C6: MATERIAL CONFLICT IDENTIFIED — PROJECT MANAGER DETERMINATION REQUIRED. Three registered records state three different positions for the same event: GBP 185,000 / 10 working days (Quotation Rev B), GBP 150,000 / 8 working days (Forecast P07-X) and GBP 210,000 / 12 working days (Risk RISK-044-X). No calculation build-up supports the quoted figures, and UP13 is internally inconsistent on the milestone variance. The registered records provide objective evidence of conflicting cost and time positions. The assistant must not decide that the Contractor assessed the compensation event incorrectly; that determination remains with Elena Brooks, NEC4 Project Manager. | D6: PROJECT MANAGER JUDGEMENT | E6: CE018_Quotation_RevB.csv / QUOT-CE018-REVB Rev B; Cost_Forecast_P07_CONFLICT.csv / FCST-P07-X Rev P07-X; Risk_Register_CONFLICT.csv / RISK-044-X Rev 7-X; P6_Activity_Export_UP13.csv / PROG-UP13, WSAE-M9000
A7: Trigger 3 — Clause 64.1, required programme alteration missing | B7: NEC-10 | C7: UP13 is a periodic current programme update linked to the quotation. It evidences changed activities — the revised sequence for WSAE-A1300, WSAE-A1400 and WSAE-M9000, with QSUB-018 referencing AP12, UP13 and those activities — but it does not conclusively establish that the specific alterations to the Accepted Programme required by Clause 62.2 were submitted as part of the quotation assessment. The assistant must not determine contractual sufficiency. This treatment is consistent with the approved S1 treatment of the same programme evidence. | D7: PROJECT MANAGER JUDGEMENT | E7: Email_06_Quotation_Submission_2026-03-28.eml / QSUB-018 Rev 1.0; P6_Activity_Export_UP13.csv / PROG-UP13; P6_Activity_Export_AP12.csv / PROG-AP12
A8: Trigger 4 — Clause 64.1, latest programme not accepted | B8: NEC-11 | C8: An Accepted Programme is available and has been used only for its registered purpose: AP12 carries accepted status and has not been substituted by UP13. No Project Manager acceptance or non-acceptance record exists for UP13 in the registered evidence, so the status of the latest programme can be neither confirmed nor excluded without inference. | D8: PROJECT MANAGER JUDGEMENT | E8: P6_Activity_Export_AP12.csv / PROG-AP12 Rev AP12; P6_Activity_Export_UP13.csv / PROG-UP13 Rev UP13; Source_Register.csv / SRC-001 Rev 3.0
A10: ="Trigger checks reported: "&COUNTA(A5:A8)&" | NOT_TRIGGERED: "&COUNTIF(D5:D8,"NOT_TRIGGERED")&" | TRIGGER_INDICATED: "&COUNTIF(D5:D8,"TRIGGER_INDICATED")&" | PROJECT MANAGER JUDGEMENT: "&COUNTIF(D5:D8,"PROJECT MANAGER JUDGEMENT") -> Trigger checks reported: 4 | NOT_TRIGGERED: 1 | TRIGGER_INDICATED: 0 | PROJECT MANAGER JUDGEMENT: 3
A11: A trigger indication is an evidence finding. It does not decide that the Contractor's assessment is incorrect, does not decide entitlement and does not determine contractual effect. Determination is reserved to Elena Brooks, NEC4 Project Manager, with a configured contractual response date of 2026-04-11 (RC-03, Clause 62.3 / 62.6).

Sheet Exceptions and Actions
A1: ASSURANCE EXCEPTIONS AND REQUIRED ACTIONS
A2: Critical assurance exceptions are counted separately from critical test failures. Assistant-assigned dates are assurance action targets, not contractual deadlines.
A4: ASSURANCE EXCEPTIONS — PAGE 1 OF 2
A5: Exception ID | B5: Category | C5: Issue | D5: Consequence | E5: Evidence | F5: Accountable owner | G5: Due date | H5: Date type | I5: Action status | J5: Retest requirement
A6: E-01 | B6: Critical | C6: Forecast P07-X conflicts with Quotation Rev B on cost and time: GBP 150,000 / 8 working days against GBP 185,000 / 10 working days. The forecast is below the quotation on all five CBS lines, a total variance of -GBP 35,000. | D6: The pack cannot evidence a single reliable commercial position. Drives T2 = 0 and is part of the material conflict referred to the Project Manager under E-03. | E6: CE018_Quotation_RevB.csv / QUOT-CE018-REVB Rev B; Cost_Forecast_P07_CONFLICT.csv / FCST-P07-X Rev P07-X, rows WSAE-C210/C310/C320/C510/C610 | F6: Sofia Khan — Project Controls Lead (forecast); Commercial Manager via Marcus Reed (quotation) | G6: 2026-04-08 | H6: Assurance action target — not a contractual deadline | I6: Open | J6: T2 and T3 must be rerun
A7: E-02 | B7: Critical | C7: Risk record RISK-044-X conflicts with Quotation Rev B on cost and time: GBP 210,000 / 12 working days against GBP 185,000 / 10 working days, a variance of +GBP 25,000 and +2 working days. | D7: A third, higher position exists for the same event with no CBS allocation. Drives T2 = 0 and is part of the material conflict referred to the Project Manager under E-03. | E7: Risk_Register_CONFLICT.csv / RISK-044-X Rev 7-X; CE018_Quotation_RevB.csv / QUOT-CE018-REVB Rev B | F7: Risk Manager | G7: 2026-04-08 | H7: Assurance action target — not a contractual deadline | I7: Open | J7: T2 and T3 must be rerun
A8: E-03 | B8: Major | C8: Material record conflict requires the Project Manager to determine whether the Contractor's assessment is incorrect for Clause 64.1 purposes. Controls NEC-09 and NEC-10 return PM_JUDGEMENT: the assistant evidences the objective conflict and the linkage of UP13 to the quotation, but must not decide that the Contractor assessed the compensation event incorrectly, and must not determine contractual sufficiency of the programme submitted. | D8: Reserved-authority exception. The determination cannot be made by the assistant at any score. It does not prevent the Project Manager's review; it is the substance of that review. | E8: NEC4_Decision_Readiness_Control_Matrix.csv / CTRL-007 Rev 1.0 rows NEC-09 and NEC-10; CE018_Control_Brief.txt / CTRL-001 Rev 3.0, Prohibited Actions | F8: Elena Brooks — NEC4 Project Manager | G8: 2026-04-11 | H8: Configured contractual response date (RC-03, Clause 62.3 / 62.6) | I8: Open — reserved to the Project Manager | J8: Not closed by assurance retest; determination is recorded by the Project Manager
A9: E-04 | B9: Major | C9: RISK-044-X carries no CBS code, so its GBP 210,000 position is not linked to a valid CBS account. The crosswalk control requires every quoted or forecast value to be linked to a valid CBS account. | D9: The risk position cannot be reconciled line by line against the quotation or forecast. Contributes to T1 = 1. | E9: Risk_Register_CONFLICT.csv / RISK-044-X Rev 7-X (no cbs_code field); CE018_WBS_Programme_CBS_Crosswalk.csv / XWALK-001 Rev 1.0 | F9: Risk Manager | G9: 2026-04-08 | H9: Assurance action target — not a contractual deadline | I9: Open | J9: T1 and T2 must be rerun
A10: E-05 | B10: Major | C10: UP13 is internally inconsistent on the milestone position, and the calendar needed to resolve it is unregistered. UP13 records a 10-working-day variance and -10 days total float at WSAE-M9000, but its own dates (AP12 2026-03-27 to UP13 2026-04-14) derive 12 working days on a plain 5-day week. The CAL-5D-10H calendar referenced by both programme exports is not registered in SRC-001 Rev 3.0. | D10: The evidenced time effect may be 10 or 12 working days. The assistant reports both readings and has not selected or repaired either. Contributes to T1 = 1 and T2 = 0. | E10: P6_Activity_Export_UP13.csv / PROG-UP13, WSAE-M9000 (variance_to_accepted_finish_working_days, total_float_days); P6_Activity_Export_AP12.csv / PROG-AP12, WSAE-M9000; Source_Register.csv / SRC-001 Rev 3.0 (no calendar record) | F10: Planning Manager | G10: 2026-04-08 | H10: Assurance action target — not a contractual deadline | I10: Open | J10: T1, T2 and T3 must be rerun
A11: ASSURANCE EXCEPTIONS (CONTINUED) — PAGE 2 OF 2
A12: Exception ID | B12: Category | C12: Issue | D12: Consequence | E12: Evidence | F12: Accountable owner | G12: Due date | H12: Date type | I12: Action status | J12: Retest requirement
A13: E-06 | B13: Major | C13: Activity WSAE-A1400 original duration increases from 7 days in AP12 to 9 days in UP13. The change is not explained in the quotation basis, the submission email or any registered record. | D13: Part of the forecast time effect may arise from a duration change rather than the access restriction. Material to the time position and to NEC-05. | E13: P6_Activity_Export_AP12.csv / PROG-AP12, WSAE-A1400 (original_duration_days 7); P6_Activity_Export_UP13.csv / PROG-UP13, WSAE-A1400 (original_duration_days 9) | F13: Marcus Reed — Contractor Delivery Lead, with Planning Manager | G13: 2026-04-08 | H13: Assurance action target — not a contractual deadline | I13: Open | J13: T2 must be rerun
A14: E-07 | B14: Major | C14: No Project Manager acceptance or non-acceptance record exists for UP13 in the registered evidence, so control NEC-11 (Clause 64.1 trigger 4) returns PM_JUDGEMENT rather than a determined result. | D14: The status of the latest programme cannot be confirmed or excluded without inference, which the assistant will not supply. No contractual programme-response date can be calculated from the registered evidence, because the date and status of submission of UP13 for acceptance are not evidenced. RC-03 relates to the quotation response and must not be used as the programme-acceptance date. | E14: P6_Activity_Export_UP13.csv / PROG-UP13 Rev UP13; Source_Register.csv / SRC-001 Rev 3.0; NEC4_Decision_Readiness_Control_Matrix.csv / CTRL-007 Rev 1.0 row NEC-11 | F14: Elena Brooks — NEC4 Project Manager | G14: 2026-04-08 | H14: Assurance action target — not a contractual deadline. No contractual programme-response date is calculable. | I14: Open — reserved to the Project Manager | J14: Not closed by assurance retest; status is recorded by the Project Manager
A15: E-08 | B15: Minor | C15: Quotation Rev B carries a narrative basis for each line but no calculation build-up — no rates, quantities or durations supporting the five amounts. | D15: Control NEC-05 (Clause 62.2) is reported CONDITIONAL rather than PASSED. The Project Manager cannot test the derivation of the quoted sums from the pack as submitted. | E15: CE018_Quotation_RevB.csv / QUOT-CE018-REVB Rev B, basis column, all 5 rows; NEC4_Decision_Readiness_Control_Matrix.csv / CTRL-007 Rev 1.0 row NEC-05 | F15: Marcus Reed — Contractor Delivery Lead | G15: 2026-04-08 | H15: Assurance action target — not a contractual deadline | I15: Open | J15: T1 and T2 must be rerun. Closure of E-08 through action A-06 is required before retest.
B16: COUNTS | C16: ="Total assurance exceptions: "&COUNTA(A6,A7,A8,A9,A10,A13,A14,A15)&" | Critical: "&COUNTIF(B6:B15,"Critical")&" | Major: "&COUNTIF(B6:B15,"Major")&" | Minor: "&COUNTIF(B6:B15,"Minor") -> Total assurance exceptions: 8 | Critical: 2 | Major: 5 | Minor: 1
A17: Critical TEST failures (tests scoring 0) are counted separately on the Four-Test Scorecard and the Executive Dashboard. The two counters measure different things and must not be combined.
A19: REQUIRED ACTIONS
A20: Action ID | B20: Action | C20: Accountable owner | D20: Due date | E20: Date type | F20: Dependency | G20: Action status | H20: Reviewer note
A21: A-01 | B21: Reconcile Forecast P07-X to Quotation Rev B line by line, or record a formal variance rationale for each CBS line. | C21: Sofia Khan — Project Controls Lead | D21: 2026-04-08 | E21: Assurance action target — not a contractual deadline | F21: E-01 | G21: Open
A22: A-02 | B22: Reconcile the RISK-044-X position to the quotation and forecast, or record a formal rationale for the higher time and cost range. | C22: Risk Manager | D22: 2026-04-08 | E22: Assurance action target — not a contractual deadline | F22: E-02 | G22: Open
A23: A-03 | B23: Apply CBS coding to RISK-044-X so its value links to a valid CBS account under XWALK-001. | C23: Risk Manager | D23: 2026-04-08 | E23: Assurance action target — not a contractual deadline | F23: E-04 | G23: Open
A24: A-04 | B24: Register the CAL-5D-10H calendar definition, including any non-working days, and confirm whether the WSAE-M9000 variance is 10 or 12 working days. | C24: Planning Manager | D24: 2026-04-08 | E24: Assurance action target — not a contractual deadline | F24: E-05 | G24: Open
A25: A-05 | B25: Explain and evidence the WSAE-A1400 duration change from 7 to 9 days, and state whether it is attributed to CE-018. | C25: Marcus Reed — Contractor Delivery Lead | D25: 2026-04-08 | E25: Assurance action target — not a contractual deadline | F25: E-06 | G25: Open
A26: A-06 | B26: Supply the calculation build-up (rates, quantities, durations) behind the five Quotation Rev B amounts. | C26: Marcus Reed — Contractor Delivery Lead | D26: 2026-04-08 | E26: Assurance action target — not a contractual deadline | F26: E-08 | G26: Open
A27: A-07 | B27: Determine whether the Contractor's assessment is incorrect for Clause 64.1 purposes, and whether the programme submitted satisfies Clause 62.2, and record both determinations. | C27: Elena Brooks — NEC4 Project Manager | D27: 2026-04-11 | E27: Configured contractual response date (RC-03, Clause 62.3 / 62.6) | F27: E-03 | G27: Reserved to the Project Manager
A28: A-08 | B28: Record the date and status of submission of UP13 for acceptance, and the acceptance or non-acceptance status, so control NEC-11 can be determined. | C28: Elena Brooks — NEC4 Project Manager | D28: 2026-04-08 | E28: Assurance action target — not a contractual deadline. No contractual programme-response date is calculable from the registered evidence. | F28: E-07 | G28: Reserved to the Project Manager
A30: ADMINISTRATIVE OBSERVATIONS — NON-ACTIONABLE, DO NOT AFFECT READINESS
A31: • Source_Register.csv / SRC-001 Rev 3.0 contains no CTRL-004 row; control references run CTRL-003 to CTRL-005. This is a register numbering gap, not a missing file.
A32: • Seven Context files and all six .eml records carry no internal revision marker, so their approved revision is asserted by SRC-001 Rev 3.0 alone.
A33: • WBS_Hierarchy.csv / WBS-001 Rev 1.0 contains milestone group WSAE.90 'Project Milestones', which is not used by the CE-018 crosswalk. WSAE-M9000 maps to WSAE.10 consistently across AP12, UP13 and XWALK-001.
A34: • The five branding PNG files are formatting assets. They are not registered in SRC-001 Rev 3.0 and have not been inventoried, cited or scored as evidence.

Sheet Decision and Audit Log
A1: DECISION AND AUDIT LOG
A2: Assessment record, route, reviewer entry and retest history. Reviewer-entry cells are shaded and unlocked.
A4: Item | B4: Value | C4: Owner | D4: Date | E4: Date type | F4: Status | G4: Reviewer entry | H4: Notes
A5: Assessment date | B5: 2026-03-31 | C5: Sofia Khan — Project Controls Lead | D5: 2026-03-31 | E5: Assessment date | F5: Complete | H5: Assurance assessment run for scenario S3.
A6: Evidence cut-off | B6: 2026-03-31 | C6: Sofia Khan — Project Controls Lead | D6: 2026-03-31 | E6: Configured cut-off (CASE-001 Rev 1.1) | F6: Applied | H6: Used to determine whether any configured response clock is overdue.
A7: Four-Test Result | B7: CRITICAL FAILURE — T2 = 0 | C7: CE-018 Assurance Assistant | D7: 2026-03-31 | E7: Assessment date | F7: Reported | H7: Total 4 of 8. T2 scores 0; T3 scores 1.
A8: Configured NEC4 Process-Assurance Result | B8: CONFIGURED NEC4 PROCESS CONTROL FAILURE — STOP / RECONCILE | C8: CE-018 Assurance Assistant | D8: 2026-03-31 | E8: Assessment date | F8: Reported | H8: All 12 configured controls run.
A9: Clause 64.1 Trigger Summary | B9: Trigger 1 NOT_TRIGGERED; Trigger 2 PROJECT MANAGER JUDGEMENT; Trigger 3 PROJECT MANAGER JUDGEMENT; Trigger 4 PROJECT MANAGER JUDGEMENT | C9: CE-018 Assurance Assistant | D9: 2026-03-31 | E9: Assessment date | F9: Reported | H9: Four checks reported separately.
A10: Recommended decision-readiness route | B10: STOP / RECONCILE | C10: CE-018 Assurance Assistant | D10: 2026-03-31 | E10: Assessment date | F10: Recommended — not a decision | H10: Route priority applied: no reserved-authority failure is present (T4 = 2, NEC-12 PASSED), so the governing condition is a material record conflict at T2 = 0. A score of 0 determines the route irrespective of the total score, so the route is unchanged from Rev 3.0 at STOP / RECONCILE. T3 scores 1 rather than 0 because every configured route and clock control is satisfied or correctly pending-not-due and no Clause 64.1 trigger indication is asserted by the assistant; the three Clause 64.1 matters referred for Project Manager judgement are bounded, owned and dated.
A11: Reviewer | B11: Elena Brooks — NEC4 Project Manager | C11: Elena Brooks | E11: Awaiting reviewer entry | F11: Not yet reviewed | H11: Reviewer to record acceptance, rework, referral or stop.
A12: Project Manager decision status | B12: Not yet decided | C12: Elena Brooks | E12: Awaiting reviewer entry | F12: Open | H12: CHG-018 Rev 5 records decision_status 'Not yet decided'.
A13: Configured contractual response date | B13: 2026-04-11 — RC-03, Clause 62.3 / 62.6 | C13: Elena Brooks | D13: 2026-04-11 | E13: Configured contractual date | F13: Pending — not due at cut-off | H13: Not overdue at the 2026-03-31 cut-off.
A14: Change register next action | B14: Review cited evidence and exceptions | C14: Elena Brooks | D14: 2026-04-02 | E14: Configured contractual date | F14: Pending — not due at cut-off | H14: Change_Register.csv / CHG-018 Rev 5.
A15: Next assurance action | B15: Close E-01, E-02, E-04, E-05, E-06 and E-08 through actions A-01 to A-06 with the named record owners, then rerun T1, T2 and T3. | C15: Sofia Khan | D15: 2026-04-08 | E15: Assurance action target — not a contractual deadline | F15: Open | H15: Assistant-assigned target.
A16: Retest history | B16: No prior retest. This is the first S3 assessment. | C16: Sofia Khan | D16: 2026-03-31 | E16: Assessment date | F16: Baseline | H16: S1 and S2 scores and routes were not carried forward; every score in this pack is assigned from the S3 evidence.
A17: Retest requirement | B17: Close E-01, E-02, E-04, E-05, E-06 and E-08 through actions A-01 to A-06 with the named record owners, then rerun T1, T2 and T3. T4 requires retest only if the requested action changes. Exceptions E-03 and E-07 are reserved to the Project Manager and are not closed by assurance retest. | C17: Sofia Khan / Elena Brooks | E17: Conditional on exception closure | F17: Open | H17: Route is reassessed only after retest.
A18: Approval | B18: Not approved. Report status: ISSUED FOR PROJECT MANAGER REVIEW (IFR). | C18: Elena Brooks | E18: Awaiting reviewer entry | F18: Not approved | H18: The assistant does not approve, accept or issue this pack contractually.
A20: Retained human authority: Elena Brooks, NEC4 Project Manager, retains every contractual decision on CE-018. The assistant prepared cited review material and took no reserved contractual action.

Sheet Source Citations
A1: SOURCE CITATIONS — DETAILED LOCATOR REGISTER
A2: Filename, record ID, revision and row / activity / WBS / CBS locator for every material finding.
A4: File name | B4: Record ID | C4: Revision / status | D4: Row / activity / WBS / CBS locator | E4: Evidence purpose | F4: Where used in this pack
A5: Source_Register.csv | B5: SRC-001 | C5: 3.0 / Current | D5: All 25 rows | E5: Controls the approved evidence inventory | F5: Evidence Register; T1; NEC-11
A6: CE018_Control_Brief.txt | B6: CTRL-001 | C6: 3.0 / Current | D6: Permitted Task; Prohibited Actions; Retained Authority | E6: Assurance method and authority boundary | F6: T4; NEC-12; Retained Human Authority
A7: Actor_Authority_Matrix.csv | B7: CTRL-002 | C7: 2.1 / Current | D7: Rows TG, MR, SK, EB, AI | E7: Named roles and reserved actions | F7: T4; NEC-12; Evidence and Correspondence Reviewed
A8: Route_Clock_Rules.csv | B8: CTRL-003 | C8: 3.0 / Current | D8: Rows RC-EW, RC-00, RC-01, RC-02, RC-03 | E8: Configured clause periods and due dates | F8: T3; NEC-01, NEC-04, NEC-06, NEC-07; Reconciliation section D
A9: Four_Test_Checklist.csv | B9: CTRL-005 | C9: 3.0 / Current | D9: Rows T1-T4 | E9: Scoring rules and critical override | F9: Four-Test Scorecard; route logic
A10: Expected_Response_Structure.txt | B10: CTRL-006 | C10: 3.0 / Current | D10: Sections 1-11 | E10: Required output structure | F10: Report and workbook structure
